Workbook
Name Selected_County: 'County Profile, 2020-2024'!$B$78

Sheet data
B1: B01001 | C1: B01001 | D1: B01001 | E1: B01001 | F1: B01001 | G1: B01001 | H1: B01001 | I1: B01001 | J1: B01001 | K1: B01001 | L1: B01001 | M1: B01001 | N1: B01001 | O1: B01002 | P1: B11006 | Q1: B11006 | R1: B11006 | S1: B11007 | T1: B11007 | U1: B12002 | V1: B12002 | W1: B12002 | X1: B12002 | Y1: B12002 | Z1: B12002 | AA1: B12002 | AB1: B12002 | AC1: B12002 | AD1: B12002 | AE1: B12002 | AF1: B12002 | AG1: B12002 | AH1: B12002 | AI1: B12002 | AJ1: B12002 | AK1: B12002 | AL1: B12002 | AM1: B12002 | AN1: B12002 | AO1: B12002 | AP1: B12002 | AQ1: B12002 | AR1: B12002 | AS1: B12002 | AT1: B12002 | AU1: B12002 | AV1: B12002 | AW1: B12002 | AX1: B12002 | AY1: B12002 | AZ1: B12002 | BA1: B12002 | BB1: B18101 | BC1: B18101 | BD1: B18101 | BE1: B18101 | BF1: B18101 | BG1: B18101 | BH1: B18101 | BI1: B18101 | BJ1: B18101 | BK1: B09020 | BL1: B09020 | BM1: B09020 | BN1: B09020 | BO1: B09020 | BP1: B09020 | BQ1: B09020 | BR1: B09020 | BS1: B09020 | BT1: AEP | BU1: AEP | BV1: AEP | BW1: AEP | BX1: AEP | BY1: AEP | BZ1: AEP | CA1: AEP | CB1: AEP | CC1: AEP | CD1: AEP | CE1: AEP | CF1: AEP | CG1: AEP | CH1: AEP | CI1: AEP | CJ1: AEP | CK1: AEP | CL1: AEP | CM1: AEP | CN1: AEP | CO1: AEP | CP1: AEP | CQ1: AEP | CR1: B01001 | CS1: B01001 | CT1: B01001 | CU1: B01001 | CV1: AEP | CW1: AEP | CX1: AEP | CY1: AEP | CZ1: AEP | DA1: AEP | DB1: AEP | DC1: AEP | DD1: B15001 | DE1: B15001 | DF1: B15001 | DG1: B15001 | DH1: B15001 | DI1: B15001 | DJ1: B15001 | DK1: B15001 | DL1: B15001 | DM1: B15001 | DN1: B15001 | DO1: B15001 | DP1: B15001 | DQ1: B15001 | DR1: B15001 | DS1: B15001 | DT1: B15001 | DU1: B15001 | DV1: B15001 | DW1: B15001 | DX1: B15001 | DY1: B15001 | DZ1: B15001 | EA1: B15001 | EB1: B19037 | EC1: B19037 | ED1: B19037 | EE1: B19037 | EF1: B19037 | EG1: B19037 | EH1: B19037 | EI1: B19037 | EJ1: B19037 | EK1: B19037 | EL1: B19037 | EM1: B19037 | EN1: B19037 | EO1: B19049 | EP1: B19049 | EQ1: B19049 | ER1: B19049 | ES1: B19049 | ET1: B17001 | EU1: B17001 | EV1: B17001 | EW1: B17001 | EX1: B17001 | EY1: B17001 | EZ1: B17001 | FA1: B17001 | FB1: B17001 | FC1: B17024 | FD1: B17024 | FE1: B17024 | FF1: B17024 | FG1: B17024 | FH1: B17024 | FI1: B17024 | FJ1: B17024 | FK1: B17024 | FL1: B17024 | FM1: B17024 | FN1: B23001 | FO1: B23001 | FP1: B23001 | FQ1: B23001 | FR1: B23001 | FS1: B23001 | FT1: B23001 | FU1: B23001 | FV1: B23001 | FW1: B23001 | FX1: B23001 | FY1: B23001 | FZ1: B23001 | GA1: B23001 | GB1: B23001 | GC1: B23001 | GD1: B23001 | GE1: B23001 | GF1: B23001 | GG1: B23001 | GH1: B25072 | GI1: B25072 | GJ1: B25072 | GK1: B25072 | GL1: B25072 | GM1: B25072 | GN1: B25072 | GO1: B25093 | GP1: B25093 | GQ1: B25093 | GR1: B25093 | GS1: B25093 | GT1: B25093
B2: Age Group Estimates | C2: Age Group Estimates | D2: Age Group Estimates | E2: Age Group Estimates | F2: Age Group Estimates | G2: Age Group Estimates | H2: Age Group Estimates | I2: Age Group Estimates | J2: Age Group Estimates | K2: Age Group Estimates | L2: Age Group Estimates | M2: Age Group Estimates | N2: Age Group Estimates | O2: Median Age | P2: Households with Older Members | Q2: Households with Older Members | R2: Households with Older Members | S2: Households with Older Members | T2: Households with Older Members | U2: Marital Status, by Sex | V2: Marital Status, by Sex | W2: Marital Status, by Sex | X2: Marital Status, by Sex | Y2: Marital Status, by Sex | Z2: Marital Status, by Sex | AA2: Marital Status, by Sex | AB2: Marital Status, by Sex | AC2: Marital Status, by Sex | AD2: Marital Status, by Sex | AE2: Marital Status, by Sex | AF2: Marital Status, by Sex | AG2: Marital Status, by Sex | AH2: Marital Status, by Sex | AI2: Marital Status, by Sex | AJ2: Marital Status, by Sex | AK2: Marital Status, by Sex | AL2: Marital Status, by Sex | AM2: Marital Status, by Sex | AN2: Marital Status, by Sex | AO2: Marital Status, by Sex | AP2: Marital Status, by Sex | AQ2: Marital Status, by Sex | AR2: Marital Status, by Sex | AS2: Marital Status, by Sex | AT2: Marital Status, by Sex | AU2: Marital Status, by Sex | AV2: Marital Status, by Sex | AW2: Marital Status, by Sex | AX2: Marital Status, by Sex | AY2: Marital Status, by Sex | AZ2: Marital Status, by Sex | BA2: Marital Status, by Sex | BB2: Disability Status, by Sex | BC2: Disability Status, by Sex | BD2: Disability Status, by Sex | BE2: Disability Status, by Sex | BF2: Disability Status, by Sex | BG2: Disability Status, by Sex | BH2: Disability Status, by Sex | BI2: Disability Status, by Sex | BJ2: Disability Status, by Sex | BK2: Living Alone | BL2: Living Alone | BM2: Living Alone | BN2: Living Alone | BO2: Living Alone | BP2: Living Alone | BQ2: Living Alone | BR2: Living Alone | BS2: Living Alone | BT2: Race & Ethnicity | BU2: Race & Ethnicity | BV2: Race & Ethnicity | BW2: Race & Ethnicity | BX2: Race & Ethnicity | BY2: Race & Ethnicity | BZ2: Race & Ethnicity | CA2: Race & Ethnicity | CB2: Race & Ethnicity | CC2: Race & Ethnicity | CD2: Race & Ethnicity | CE2: Race & Ethnicity | CF2: Race & Ethnicity | CG2: Race & Ethnicity | CH2: Race & Ethnicity | CI2: Race & Ethnicity | CJ2: Race & Ethnicity | CK2: Race & Ethnicity | CL2: Race & Ethnicity | CM2: Race & Ethnicity | CN2: Race & Ethnicity | CO2: Race & Ethnicity | CP2: Race & Ethnicity | CQ2: Race & Ethnicity | CR2: Race & Ethnicity | CS2: Race & Ethnicity | CT2: Race & Ethnicity | CU2: Race & Ethnicity | CV2: Race & Ethnicity | CW2: Race & Ethnicity | CX2: Race & Ethnicity | CY2: Race & Ethnicity | CZ2: Race & Ethnicity | DA2: Race & Ethnicity | DB2: Race & Ethnicity | DC2: Race & Ethnicity | DD2: Educational Attainment | DE2: Educational Attainment | DF2: Educational Attainment | DG2: Educational Attainment | DH2: Educational Attainment | DI2: Educational Attainment | DJ2: Educational Attainment | DK2: Educational Attainment | DL2: Educational Attainment | DM2: Educational Attainment | DN2: Educational Attainment | DO2: Educational Attainment | DP2: Educational Attainment | DQ2: Educational Attainment | DR2: Educational Attainment | DS2: Educational Attainment | DT2: Educational Attainment | DU2: Educational Attainment | DV2: Educational Attainment | DW2: Educational Attainment | DX2: Educational Attainment | DY2: Educational Attainment | DZ2: Educational Attainment | EA2: Educational Attainment | EB2: Household Income | EC2: Household Income | ED2: Household Income | EE2: Household Income | EF2: Household Income | EG2: Household Income | EH2: Household Income | EI2: Household Income | EJ2: Household Income | EK2: Household Income | EL2: Household Income | EM2: Household Income | EN2: Household Income | EO2: Median Household Income | EP2: Median Household Income | EQ2: Median Household Income | ER2: Median Household Income | ES2: Median Household Income | ET2: Poverty by Sex | EU2: Poverty by Sex | EV2: Poverty by Sex | EW2: Poverty by Sex | EX2: Poverty by Sex | EY2: Poverty by Sex | EZ2: Poverty by Sex | FA2: Poverty by Sex | FB2: Poverty by Sex | FC2: Ratio of Income to Poverty | FD2: Ratio of Income to Poverty | FE2: Ratio of Income to Poverty | FF2: Ratio of Income to Poverty | FG2: Ratio of Income to Poverty | FH2: Ratio of Income to Poverty | FI2: Ratio of Income to Poverty | FJ2: Ratio of Income to Poverty | FK2: Ratio of Income to Poverty | FL2: Ratio of Income to Poverty | FM2: Ratio of Income to Poverty | FN2: Employment Status | FO2: Employment Status | FP2: Employment Status | FQ2: Employment Status | FR2: Employment Status | FS2: Employment Status | FT2: Employment Status | FU2: Employment Status | FV2: Employment Status | FW2: Employment Status | FX2: Employment Status | FY2: Employment Status | FZ2: Employment Status | GA2: Employment Status | GB2: Employment Status | GC2: Employment Status | GD2: Employment Status | GE2: Employment Status | GF2: Employment Status | GG2: Employment Status | GH2: Housing Tenure and Costs | GI2: Housing Tenure and Costs | GJ2: Housing Tenure and Costs | GK2: Housing Tenure and Costs | GL2: Housing Tenure and Costs | GM2: Housing Tenure and Costs | GN2: Housing Tenure and Costs | GO2: Housing Tenure and Costs | GP2: Housing Tenure and Costs | GQ2: Housing Tenure and Costs | GR2: Housing Tenure and Costs | GS2: Housing Tenure and Costs | GT2: Housing Tenure and Costs
B3: Total Population - All Ages, All Races | C3: 60+ | D3: 65+ | E3: 75+ | F3: 85+ | G3: % 60+ | H3: % 65+ | I3: % 75+ | J3: % 85+ | K3: Males age 65+ | L3: Males as percent of 65+ population | M3: Females age 65+ | N3: Females as percent of 65+ population | O3: Total (Males and Females, All Races) | P3: Total number of households | Q3: Households with one or more people 60 years and over: | R3: Percent with a member age 60+ | S3: Households with one or more people 65 years and over: | T3: Percent with a member age 65+ | U3: Total Males, 65+ | V3: Males, 65+: Never Married | W3: % Males Never Married | X3: Males, 65+: Married, Spouse Present | Y3: % Males Married, Spouse Present | Z3: Males, 65+: Married, Spouse Absent (e.g., Separated) | AA3: % Males Married, Spouse Absent | AB3: Males, 65+: Widowed | AC3: % Males Widowed | AD3: Males, 65+: Divorced | AE3: % Males Divorced | AF3: Total Females, 65+ | AG3: Females, 65+: Never Married | AH3: % Females Never Married | AI3: Females, 65+: Married, Spouse Present | AJ3: % Females Married, Spouse Present | AK3: Females, 65+: Married, Spouse Absent (e.g., Separated) | AL3: % Females Married, Spouse Absent | AM3: Females, 65+: Widowed | AN3: % Females Widowed | AO3: Females, 65+: Divorced | AP3: % Females Divorced | AQ3: Total Persons, 65+ | AR3: Persons, 65+: Never Married | AS3: % Total Never Married | AT3: Persons, 65+: Married, Spouse Present | AU3: % Total Married, Spouse Present | AV3: Persons, 65+: Married, Spouse Absent (e.g., Separated) | AW3: % Total Married, Spouse Absent | AX3: Persons, 65+: Widowed | AY3: % Total Widowed | AZ3: Persons, 65+: Divorced | BA3: % Total Divorced | BB3: Males, 65+, Total* | BC3: Males, 65+, With a Disability | BD3: Males, 65+, % with a Disability | BE3: Females, 65+, Total* | BF3: Females, 65+, With a Disability | BG3: Females, 65+, % with a Disability | BH3: All Persons, 65+* | BI3: Total Persons, 65+, With a Disability | BJ3: Total Persons, 65+, % with a Disability | BK3: Persons 65+ | BL3: Persons 65+ living alone | BM3: Persons, % living alone | BN3: Males age 65+ | BO3: Males age 65+ living alone | BP3: Males, % living alone | BQ3: Females age 65+ | BR3: Females age 65+ living alone | BS3: Females, % living alone | BT3: Total - All Ages: Total Population | BU3: 65+ All Races and Hispanic Ethnicity | BV3: % of Total Population that is 65+ | BW3: % of 65+ that is All Races and Hispanic Ethnicity | BX3: Total - All Ages: White/Caucasian Alone | BY3: 65+ White/Caucasian | BZ3: % of White/Caucasian pop that is 65+ | CA3: % of 65+ that is White/Caucasian | CB3: Total - All Ages: Black/African American Alone | CC3: 65+ Black/African American | CD3: % of Black/African American pop that is 65+ | CE3: % of 65+ that is Black/African American | CF3: Total - All Ages: Native American/Alaska Native Alone | CG3: 65+ Native American/Alaska Native | CH3: % of Native American/Alaska Native pop that is 65+ | CI3: % of 65+ that is Native American/Alaska Native | CJ3: Total - All Ages: Asian Alone | CK3: 65+ Asian | CL3: % of Asian pop that is 65+ | CM3: % of 65+ that is Asian | CN3: Total - All Ages: Hawaiian/Pacific Islander Alone | CO3: 65+ Hawaiian/Pacific Islander | CP3: % of Hawaiian/Pacific Islander pop that is 65+ | CQ3: % of 65+ that is Hawaiian/Pacific Islander | CR3: Total - All Ages: Some Other Race | CS3: 65+ Some Other Race | CT3: % of Some Other Race pop that is 65+ | CU3: % of 65+ that is Some Other Race | CV3: Total - All Ages: Two or More Races | CW3: 65+ Two or More Races | CX3: % of Two or More Races pop that is 65+ | CY3: % of 65+ that is Two or More Races | CZ3: Total - All Ages: Ethnicity Hispanic/Latino (May be any Race) | DA3: 65+ with Ethnicity Hispanic/Latino | DB3: % of Ethnicity Hispanic/Latino pop that is 65+ | DC3: % of 65+ with Ethnicity Hispanic/Latino | DD3: Males: 65 years and over: | DE3: 65+ Males: Less than high school graduate | DF3: 65+ Males: High school graduate (includes equiv.) | DG3: 65+ Males: Some college or associate's degree | DH3: 65+ Males: Bachelor's degree or higher | DI3: % 65+ Males: Less than high school | DJ3: % 65+ Males: High school only | DK3: % 65+ Males: More than high school | DL3: Females: 65 years and over: | DM3: 65+ Females: Less than high school graduate | DN3: 65+ Females: High school graduate (includes equiv) | DO3: 65+ Females: Some college or associate's degree | DP3: 65+ Females: Bachelor's degree or higher | DQ3: % 65+ Females: Less than high school | DR3: % 65+ Females: High school only | DS3: % 65+ Females: More than high school | DT3: Persons: 65 years and over: | DU3: 65+ Persons: Less than high school graduate | DV3: 65+ Persons: High school graduate (includes equiv) | DW3: 65+ Persons: Some college or associate's degree | DX3: 65+ Persons: Bachelor's degree or higher | DY3: % 65+ Persons: Less than high school | DZ3: % 65+ Persons: High school only | EA3: % 65+ Persons: More than high school | EB3: Households with head age 65+ | EC3: Household income below $15,000 | ED3: % with HH income below $15,000 | EE3: Household income below $25,000 | EF3: % with HH income below $25,000 | EG3: Household income below $35,000 | EH3: % with HH income below $35,000 | EI3: Household income below $50,000 | EJ3: % with HH income below $50,000 | EK3: Household income below $75,000 | EL3: % with HH income below $75,000 | EM3: Household income below $100,000 | EN3: % with HH income below $100,000 | EO3: Total, householders of all ages: | EP3: Householder under 25 years | EQ3: Householder 25 to 44 years | ER3: Householder 45 to 64 years | ES3: Householder 65 years and over | ET3: Males age 65+ (for poverty) | EU3: 65+ Males in Poverty | EV3: % of 65+ males in poverty | EW3: Females age 65+ (for poverty) | EX3: 65+ Females in Poverty | EY3: % of 65+ females in poverty | EZ3: Persons age 65+ (for poverty) | FA3: Persons 65+ in poverty | FB3: % of persons 65+ in poverty | FC3: Total, Age 65+* | FD3: Age 65+ below poverty | FE3: % of 65+ Pop below poverty | FF3: Age 65+: 150% of poverty or less | FG3: % of 65+ Pop: 150% of poverty or less | FH3: Age 65+: 185% of poverty or less | FI3: % of 65+ Pop: 185% of poverty or less | FJ3: Age 65+: 200% of poverty or less | FK3: % of 65+ Pop: 200% of poverty or less | FL3: Age 65+: 300% of poverty or less | FM3: % of 65+ Pop: 300% of poverty or less | FN3: Males age 65-74: Employed | FO3: Males 65-74; % Employed | FP3: Males age 65-74: Unemployed | FQ3: Males 65-74; % Unemployed | FR3: Males age 75+: Employed | FS3: Males 75+; % Employed | FT3: Males age 75+: Unemployed | FU3: Males 75+; % Unemployed | FV3: Females age 65-74: Employed | FW3: Females 65-74; % Employed | FX3: Females age 65-74: Unemployed | FY3: Females 65-74; % Unemployed | FZ3: Females age 75+: Employed | GA3: Females 75+; % Employed | GB3: Females age 75+: Unemployed | GC3: Females 75+; % Unemployed | GD3: Persons age 65+: Employed | GE3: Persons age 65+; % Employed | GF3: Persons age 65+: Unemployed | GG3: Persons age 65+; % Unemployed | GH3: Housing units occupied by householders age 65+ | GI3: Number of units that are rentals | GJ3: Percent of units that are rentals | GK3: Rental costs less than 30% of income | GL3: Percent with rental costs <30% of income | GM3: Rental costs 30% of income or more | GN3: Percent with rental costs >=30% of income or more | GO3: Number of units that are owner-occupied | GP3: Percent of units that are owner-occupied | GQ3: Monthly owner costs less than 30% of income | GR3: Percent with monthly owner costs <30% of income | GS3: Monthly owner costs 30% of income or more | GT3: Percent with owner costs >=30% of income
A4: Wisconsin | B4: 5914872 | C4: 1514099 | D4: 1096043 | E4: 434379 | F4: 124459 | G4: =C4/B4 -> 0.2559817 | H4: =D4/B4 -> 0.18530291 | I4: =E4/B4 -> 0.073438445 | J4: =F4/B4 -> 0.021041706 | K4: 510727 | L4: =K4/D4 -> 0.46597351 | M4: 585316 | N4: =M4/D4 -> 0.53402649 | O4: 40.2 | P4: 2479480 | Q4: 1033712 | R4: =Q4/P4 -> 0.41690677 | S4: 778619 | T4: =S4/P4 -> 0.31402512 | U4: 510727 | V4: 35830 | W4: =V4/U4 -> 0.070154897 | X4: 343234 | Y4: =X4/U4 -> 0.67204984 | Z4: 14953 | AA4: =Z4/U4 -> 0.029277873 | AB4: 50209 | AC4: =AB4/U4 -> 0.098308881 | AD4: 66501 | AE4: =AD4/U4 -> 0.13020851 | AF4: 585316 | AG4: 37140 | AH4: =AG4/AF4 -> 0.063452904 | AI4: 275664 | AJ4: =AI4/AF4 -> 0.47096611 | AK4: 14366 | AL4: =AK4/AF4 -> 0.024544007 | AM4: 165331 | AN4: =AM4/AF4 -> 0.28246451 | AO4: 92815 | AP4: =AO4/AF4 -> 0.15857246 | AQ4: =SUM(U4,AF4) -> 1096043 | AR4: =SUM(V4,AG4) -> 72970 | AS4: =AR4/AQ4 -> 0.066575855 | AT4: =SUM(X4,AI4) -> 618898 | AU4: =AT4/AQ4 -> 0.5646658 | AV4: =SUM(Z4,AK4) -> 29319 | AW4: =AV4/AQ4 -> 0.026749863 | AX4: =SUM(AB4,AM4) -> 215540 | AY4: =AX4/AQ4 -> 0.19665287 | AZ4: =SUM(AD4,AO4) -> 159316 | BA4: =AZ4/AQ4 -> 0.14535561 | BB4: 501270 | BC4: 144564 | BD4: =BC4/BB4 -> 0.28839548 | BE4: 568121 | BF4: 159656 | BG4: =BF4/BE4 -> 0.28102464 | BH4: =SUM(BB4,BE4) -> 1069391 | BI4: =SUM(BC4,BF4) -> 304220 | BJ4: =BI4/BH4 -> 0.28447967 | BK4: 1096043 | BL4: 320658 | BM4: =BL4/BK4 -> 0.29255969 | BN4: 510727 | BO4: 109743 | BP4: =BO4/BN4 -> 0.21487605 | BQ4: 585316 | BR4: 210915 | BS4: =BR4/BQ4 -> 0.36034381 | BT4: 5960975 | BU4: 1168733 | BV4: =BU4/BT4 -> 0.19606407 | BW4: =BU4/$BU4 -> 1 | BX4: 4704156 | BY4: 1076580 | BZ4: =BY4/BX4 -> 0.22885721 | CA4: =BY4/$BU4 -> 0.92115137 | CB4: 376518 | CC4: 36846 | CD4: =CC4/CB4 -> 0.097859863 | CE4: =CC4/$BU4 -> 0.031526448 | CF4: 52129 | CG4: 7377 | CH4: =CG4/CF4 -> 0.14151432 | CI4: =CG4/$BU4 -> 0.0063119635 | CJ4: 206457 | CK4: 14292 | CL4: =CK4/CJ4 -> 0.069225069 | CM4: =CK4/$BU4 -> 0.012228627 | CN4: 2518 | CO4: 299 | CP4: =CO4/CN4 -> 0.11874504 | CQ4: =CO4/$BU4 -> 0.0002558326 | CR4: 92690 | CS4: 2381 | CT4: =CS4/CR4 -> 0.025687776 | CU4: =CS4/$BU4 -> 0.0020372489 | CV4: 118928 | CW4: 5630 | CX4: =CW4/CV4 -> 0.047339567 | CY4: =CW4/$BU4 -> 0.0048171824 | CZ4: 500269 | DA4: 27709 | DB4: =DA4/CZ4 -> 0.055388201 | DC4: =DA4/$BU4 -> 0.02370858 | DD4: 510727 | DE4: 37962 | DF4: 179581 | DG4: 142801 | DH4: 150383 | DI4: =DE4/DD4 -> 0.074329338 | DJ4: =DF4/DD4 -> 0.35161838 | DK4: =SUM(DG4:DH4)/DD4 -> 0.57405228 | DL4: 585316 | DM4: 39828 | DN4: 230513 | DO4: 164474 | DP4: 150501 | DQ4: =DM4/DL4 -> 0.068045295 | DR4: =DN4/DL4 -> 0.39382658 | DS4: =SUM(DO4:DP4)/DL4 -> 0.53812812 | DT4: =SUM(DL4,DD4) -> 1096043 | DU4: =SUM(DM4,DE4) -> 77790 | DV4: =SUM(DN4,DF4) -> 410094 | DW4: =SUM(DO4,DG4) -> 307275 | DX4: =SUM(DP4,DH4) -> 300884 | DY4: =DU4/DT4 -> 0.070973493 | DZ4: =DV4/DT4 -> 0.37415868 | EA4: =SUM(DW4:DX4)/DT4 -> 0.55486783 | EB4: 704634 | EC4: 62109 | ED4: =EC4/$EB4 -> 0.088143632 | EE4: 129765 | EF4: =EE4/$EB4 -> 0.18415944 | EG4: 215008 | EH4: =EG4/$EB4 -> 0.3051343 | EI4: 309613 | EJ4: =EI4/$EB4 -> 0.43939549 | EK4: 454481 | EL4: =EK4/$EB4 -> 0.64498875 | EM4: 546311 | EN4: =EM4/$EB4 -> 0.77531172 | EO4: 77485 | EP4: 45850 | EQ4: 90128 | ER4: 94903 | ES4: 56488 | ET4: 501270 | EU4: 37828 | EV4: =EU4/ET4 -> 0.075464321 | EW4: 568121 | EX4: 59402 | EY4: =EX4/EW4 -> 0.10455871 | EZ4: =SUM(ET4,EW4) -> 1069391 | FA4: =SUM(EU4,EX4) -> 97230 | FB4: =FA4/EZ4 -> 0.090920907 | FC4: 1069391 | FD4: 97230 | FE4: =FD4/$FC4 -> 0.090920907 | FF4: 170118 | FG4: =FF4/$FC4 -> 0.15907933 | FH4: 234788 | FI4: =FH4/$FC4 -> 0.219553 | FJ4: 271979 | FK4: =FJ4/$FC4 -> 0.25433074 | FL4: 461898 | FM4: =FL4/$FC4 -> 0.43192621 | FN4: 85607 | FO4: 0.26448199 | FP4: 1872 | FQ4: 0.0057835256 | FR4: 15521 | FS4: 0.082978257 | FT4: 187 | FU4: 0.00099973804 | FV4: 70927 | FW4: 0.20985189 | FX4: 1471 | FY4: 0.0043522513 | FZ4: 11118 | GA4: 0.044952088 | GB4: 313 | GC4: 0.0012655157 | GD4: 183173 | GE4: 0.16712209 | GF4: 3843 | GG4: 0.0035062493 | GH4: 704634 | GI4: 158043 | GJ4: =GI4/GH4 -> 0.22429091 | GK4: 56619 | GL4: =GK4/GI4 -> 0.3582506 | GM4: 87122 | GN4: =GM4/GI4 -> 0.55125504 | GO4: 546591 | GP4: =GO4/GH4 -> 0.77570909 | GQ4: 413533 | GR4: =GQ4/GO4 -> 0.75656752 | GS4: 128749 | GT4: =GS4/GO4 -> 0.23554907
A5: Adams | B5: 21123 | C5: 9045 | D5: 6803 | E5: 2595 | F5: 668 | G5: =C5/B5 -> 0.42820622 | H5: =D5/B5 -> 0.32206599 | I5: =E5/B5 -> 0.12285187 | J5: =F5/B5 -> 0.031624296 | K5: 3531 | L5: =K5/D5 -> 0.51903572 | M5: 3272 | N5: =M5/D5 -> 0.48096428 | O5: 55.7 | P5: 9517 | Q5: 5968 | R5: =Q5/P5 -> 0.62708837 | S5: 4721 | T5: =S5/P5 -> 0.49605968 | U5: 3531 | V5: 148 | W5: =V5/U5 -> 0.041914472 | X5: 2326 | Y5: =X5/U5 -> 0.6587369 | Z5: 91 | AA5: =Z5/U5 -> 0.025771736 | AB5: 325 | AC5: =AB5/U5 -> 0.092041914 | AD5: 641 | AE5: =AD5/U5 -> 0.18153498 | AF5: 3272 | AG5: 165 | AH5: =AG5/AF5 -> 0.050427873 | AI5: 1739 | AJ5: =AI5/AF5 -> 0.53147922 | AK5: 68 | AL5: =AK5/AF5 -> 0.020782396 | AM5: 836 | AN5: =AM5/AF5 -> 0.25550122 | AO5: 464 | AP5: =AO5/AF5 -> 0.14180929 | AQ5: =SUM(U5,AF5) -> 6803 | AR5: =SUM(V5,AG5) -> 313 | AS5: =AR5/AQ5 -> 0.046009114 | AT5: =SUM(X5,AI5) -> 4065 | AU5: =AT5/AQ5 -> 0.5975305 | AV5: =SUM(Z5,AK5) -> 159 | AW5: =AV5/AQ5 -> 0.023372042 | AX5: =SUM(AB5,AM5) -> 1161 | AY5: =AX5/AQ5 -> 0.17066 | AZ5: =SUM(AD5,AO5) -> 1105 | BA5: =AZ5/AQ5 -> 0.16242834 | BB5: 3519 | BC5: 1240 | BD5: =BC5/BB5 -> 0.35237283 | BE5: 3241 | BF5: 1130 | BG5: =BF5/BE5 -> 0.34865782 | BH5: =SUM(BB5,BE5) -> 6760 | BI5: =SUM(BC5,BF5) -> 2370 | BJ5: =BI5/BH5 -> 0.35059172 | BK5: 6803 | BL5: 1740 | BM5: =BL5/BK5 -> 0.25576951 | BN5: 3531 | BO5: 901 | BP5: =BO5/BN5 -> 0.25516851 | BQ5: 3272 | BR5: 839 | BS5: =BR5/BQ5 -> 0.25641809 | BT5: 21352 | BU5: 7276 | BV5: =BU5/BT5 -> 0.34076433 | BW5: =BU5/$BU5 -> 1 | BX5: 19105 | BY5: 7026 | BZ5: =BY5/BX5 -> 0.36775713 | CA5: =BY5/$BU5 -> 0.96564046 | CB5: 624 | CC5: 47 | CD5: =CC5/CB5 -> 0.075320513 | CE5: =CC5/$BU5 -> 0.0064595932 | CF5: 201 | CG5: 33 | CH5: =CG5/CF5 -> 0.1641791 | CI5: =CG5/$BU5 -> 0.004535459 | CJ5: 137 | CK5: 26 | CL5: =CK5/CJ5 -> 0.18978102 | CM5: =CK5/$BU5 -> 0.003573392 | CN5: 7 | CO5: 1 | CP5: =CO5/CN5 -> 0.14285714 | CQ5: =CO5/$BU5 -> 0.00013743815 | CR5: 126 | CS5: 11 | CT5: =CS5/CR5 -> 0.087301587 | CU5: =CS5/$BU5 -> 0.0015118197 | CV5: 291 | CW5: 47 | CX5: =CW5/CV5 -> 0.16151203 | CY5: =CW5/$BU5 -> 0.0064595932 | CZ5: 987 | DA5: 96 | DB5: =DA5/CZ5 -> 0.097264438 | DC5: =DA5/BU5 -> 0.013194063 | DD5: 3531 | DE5: 458 | DF5: 1466 | DG5: 923 | DH5: 684 | DI5: =DE5/DD5 -> 0.1297083 | DJ5: =DF5/DD5 -> 0.41517984 | DK5: =SUM(DG5:DH5)/DD5 -> 0.45511187 | DL5: 3272 | DM5: 319 | DN5: 1372 | DO5: 1095 | DP5: 486 | DQ5: =DM5/DL5 -> 0.097493888 | DR5: =DN5/DL5 -> 0.4193154 | DS5: =SUM(DO5:DP5)/DL5 -> 0.48319071 | DT5: =SUM(DL5,DD5) -> 6803 | DU5: =SUM(DM5,DE5) -> 777 | DV5: =SUM(DN5,DF5) -> 2838 | DW5: =SUM(DO5,DG5) -> 2018 | DX5: =SUM(DP5,DH5) -> 1170 | DY5: =DU5/DT5 -> 0.11421432 | DZ5: =DV5/DT5 -> 0.4171689 | EA5: =SUM(DW5:DX5)/DT5 -> 0.46861679 | EB5: 4285 | EC5: 392 | ED5: =EC5/$EB5 -> 0.091481914 | EE5: 835 | EF5: =EE5/$EB5 -> 0.19486581 | EG5: 1531 | EH5: =EG5/$EB5 -> 0.35729288 | EI5: 2315 | EJ5: =EI5/$EB5 -> 0.54025671 | EK5: 3163 | EL5: =EK5/$EB5 -> 0.73815636 | EM5: 3658 | EN5: =EM5/$EB5 -> 0.85367561 | EO5: 59442 | EP5: 67500 | EQ5: 69730 | ER5: 80799 | ES5: 47002 | ET5: 3519 | EU5: 311 | EV5: =EU5/ET5 -> 0.08837738 | EW5: 3241 | EX5: 534 | EY5: =EX5/EW5 -> 0.16476396 | EZ5: =SUM(ET5,EW5) -> 6760 | FA5: =SUM(EU5,EX5) -> 845 | FB5: =FA5/EZ5 -> 0.125 | FC5: 6760 | FD5: 845 | FE5: =FD5/$FC5 -> 0.125 | FF5: 1442 | FG5: =FF5/$FC5 -> 0.21331361 | FH5: 1873 | FI5: =FH5/$FC5 -> 0.27707101 | FJ5: 2380 | FK5: =FJ5/$FC5 -> 0.35207101 | FL5: 3744 | FM5: =FL5/$FC5 -> 0.55384615 | FN5: 362 | FO5: 0.16153503 | FP5: 2 | FQ5: 0.00089245872 | FR5: 72 | FS5: 0.055813953 | FT5: 1 | FU5: 0.0007751938 | FV5: 267 | FW5: 0.13573971 | FX5: 3 | FY5: 0.0015251652 | FZ5: 125 | GA5: 0.095785441 | GB5: 0 | GC5: 0 | GD5: 826 | GE5: 0.12141702 | GF5: 6 | GG5: 0.00088196384 | GH5: 4285 | GI5: 333 | GJ5: =GI5/GH5 -> 0.077712952 | GK5: 104 | GL5: =GK5/GI5 -> 0.31231231 | GM5: 126 | GN5: =GM5/GI5 -> 0.37837838 | GO5: 3952 | GP5: =GO5/GH5 -> 0.92228705 | GQ5: 2866 | GR5: =GQ5/GO5 -> 0.72520243 | GS5: 1052 | GT5: =GS5/GO5 -> 0.26619433
A6: Ashland | B6: 16080 | C6: 4731 | D6: 3452 | E6: 1316 | F6: 459 | G6: =C6/B6 -> 0.29421642 | H6: =D6/B6 -> 0.21467662 | I6: =E6/B6 -> 0.081840796 | J6: =F6/B6 -> 0.028544776 | K6: 1683 | L6: =K6/D6 -> 0.48754345 | M6: 1769 | N6: =M6/D6 -> 0.51245655 | O6: 43.1 | P6: 6832 | Q6: 3251 | R6: =Q6/P6 -> 0.47584895 | S6: 2483 | T6: =S6/P6 -> 0.36343677 | U6: 1683 | V6: 159 | W6: =V6/U6 -> 0.094474153 | X6: 973 | Y6: =X6/U6 -> 0.57813428 | Z6: 54 | AA6: =Z6/U6 -> 0.032085561 | AB6: 210 | AC6: =AB6/U6 -> 0.12477718 | AD6: 287 | AE6: =AD6/U6 -> 0.17052882 | AF6: 1769 | AG6: 153 | AH6: =AG6/AF6 -> 0.086489542 | AI6: 815 | AJ6: =AI6/AF6 -> 0.46071227 | AK6: 51 | AL6: =AK6/AF6 -> 0.028829847 | AM6: 434 | AN6: =AM6/AF6 -> 0.24533635 | AO6: 316 | AP6: =AO6/AF6 -> 0.178632 | AQ6: =SUM(U6,AF6) -> 3452 | AR6: =SUM(V6,AG6) -> 312 | AS6: =AR6/AQ6 -> 0.090382387 | AT6: =SUM(X6,AI6) -> 1788 | AU6: =AT6/AQ6 -> 0.5179606 | AV6: =SUM(Z6,AK6) -> 105 | AW6: =AV6/AQ6 -> 0.030417149 | AX6: =SUM(AB6,AM6) -> 644 | AY6: =AX6/AQ6 -> 0.18655852 | AZ6: =SUM(AD6,AO6) -> 603 | BA6: =AZ6/AQ6 -> 0.17468134 | BB6: 1600 | BC6: 534 | BD6: =BC6/BB6 -> 0.33375 | BE6: 1680 | BF6: 509 | BG6: =BF6/BE6 -> 0.30297619 | BH6: =SUM(BB6,BE6) -> 3280 | BI6: =SUM(BC6,BF6) -> 1043 | BJ6: =BI6/BH6 -> 0.3179878 | BK6: 3452 | BL6: 1154 | BM6: =BL6/BK6 -> 0.33429896 | BN6: 1683 | BO6: 494 | BP6: =BO6/BN6 -> 0.29352347 | BQ6: 1769 | BR6: 660 | BS6: =BR6/BQ6 -> 0.37309214 | BT6: 16196 | BU6: 3708 | BV6: =BU6/BT6 -> 0.22894542 | BW6: =BU6/$BU6 -> 1 | BX6: 13277 | BY6: 3295 | BZ6: =BY6/BX6 -> 0.24817353 | CA6: =BY6/$BU6 -> 0.8886192 | CB6: 112 | CC6: 8 | CD6: =CC6/CB6 -> 0.071428571 | CE6: =CC6/$BU6 -> 0.0021574973 | CF6: 1595 | CG6: 260 | CH6: =CG6/CF6 -> 0.1630094 | CI6: =CG6/$BU6 -> 0.070118662 | CJ6: 157 | CK6: 17 | CL6: =CK6/CJ6 -> 0.10828025 | CM6: =CK6/$BU6 -> 0.0045846818 | CN6: 6 | CO6: 0 | CP6: =CO6/CN6 -> 0 | CQ6: =CO6/$BU6 -> 0 | CR6: 44 | CS6: 0 | CT6: =CS6/CR6 -> 0 | CU6: =CS6/$BU6 -> 0 | CV6: 531 | CW6: 87 | CX6: =CW6/CV6 -> 0.16384181 | CY6: =CW6/$BU6 -> 0.023462783 | CZ6: 518 | DA6: 41 | DB6: =DA6/CZ6 -> 0.079150579 | DC6: =DA6/BU6 -> 0.011057174 | DD6: 1683 | DE6: 91 | DF6: 697 | DG6: 525 | DH6: 370 | DI6: =DE6/DD6 -> 0.054070113 | DJ6: =DF6/DD6 -> 0.41414141 | DK6: =SUM(DG6:DH6)/DD6 -> 0.53178847 | DL6: 1769 | DM6: 54 | DN6: 834 | DO6: 515 | DP6: 366 | DQ6: =DM6/DL6 -> 0.030525721 | DR6: =DN6/DL6 -> 0.4714528 | DS6: =SUM(DO6:DP6)/DL6 -> 0.49802148 | DT6: =SUM(DL6,DD6) -> 3452 | DU6: =SUM(DM6,DE6) -> 145 | DV6: =SUM(DN6,DF6) -> 1531 | DW6: =SUM(DO6,DG6) -> 1040 | DX6: =SUM(DP6,DH6) -> 736 | DY6: =DU6/DT6 -> 0.042004635 | DZ6: =DV6/DT6 -> 0.44351101 | EA6: =SUM(DW6:DX6)/DT6 -> 0.51448436 | EB6: 2292 | EC6: 410 | ED6: =EC6/$EB6 -> 0.17888307 | EE6: 665 | EF6: =EE6/$EB6 -> 0.29013962 | EG6: 940 | EH6: =EG6/$EB6 -> 0.41012216 | EI6: 1236 | EJ6: =EI6/$EB6 -> 0.53926702 | EK6: 1712 | EL6: =EK6/$EB6 -> 0.7469459 | EM6: 1918 | EN6: =EM6/$EB6 -> 0.83682373 | EO6: 62462 | EP6: 56667 | EQ6: 70406 | ER6: 75422 | ES6: 44602 | ET6: 1600 | EU6: 227 | EV6: =EU6/ET6 -> 0.141875 | EW6: 1680 | EX6: 345 | EY6: =EX6/EW6 -> 0.20535714 | EZ6: =SUM(ET6,EW6) -> 3280 | FA6: =SUM(EU6,EX6) -> 572 | FB6: =FA6/EZ6 -> 0.17439024 | FC6: 3280 | FD6: 572 | FE6: =FD6/$FC6 -> 0.17439024 | FF6: 869 | FG6: =FF6/$FC6 -> 0.26493902 | FH6: 1048 | FI6: =FH6/$FC6 -> 0.3195122 | FJ6: 1198 | FK6: =FJ6/$FC6 -> 0.3652439 | FL6: 1736 | FM6: =FL6/$FC6 -> 0.52926829 | FN6: 240 | FO6: 0.21937843 | FP6: 2 | FQ6: 0.0018281536 | FR6: 75 | FS6: 0.12733447 | FT6: 2 | FU6: 0.0033955857 | FV6: 240 | FW6: 0.2303263 | FX6: 3 | FY6: 0.0028790787 | FZ6: 67 | GA6: 0.09215956 | GB6: 1 | GC6: 0.0013755158 | GD6: 622 | GE6: 0.1801854 | GF6: 8 | GG6: 0.0023174971 | GH6: 2292 | GI6: 487 | GJ6: =GI6/GH6 -> 0.21247818 | GK6: 166 | GL6: =GK6/GI6 -> 0.34086242 | GM6: 243 | GN6: =GM6/GI6 -> 0.49897331 | GO6: 1805 | GP6: =GO6/GH6 -> 0.78752182 | GQ6: 1361 | GR6: =GQ6/GO6 -> 0.75401662 | GS6: 439 | GT6: =GS6/GO6 -> 0.2432133
A7: Barron | B7: 46797 | C7: 14886 | D7: 11028 | E7: 4690 | F7: 1241 | G7: =C7/B7 -> 0.31809731 | H7: =D7/B7 -> 0.23565613 | I7: =E7/B7 -> 0.1002201 | J7: =F7/B7 -> 0.026518794 | K7: 5326 | L7: =K7/D7 -> 0.48295248 | M7: 5702 | N7: =M7/D7 -> 0.51704752 | O7: 44.9 | P7: 19955 | Q7: 10027 | R7: =Q7/P7 -> 0.50248058 | S7: 7708 | T7: =S7/P7 -> 0.38626911 | U7: 5326 | V7: 322 | W7: =V7/U7 -> 0.06045813 | X7: 3609 | Y7: =X7/U7 -> 0.67761923 | Z7: 196 | AA7: =Z7/U7 -> 0.036800601 | AB7: 465 | AC7: =AB7/U7 -> 0.087307548 | AD7: 734 | AE7: =AD7/U7 -> 0.13781449 | AF7: 5702 | AG7: 280 | AH7: =AG7/AF7 -> 0.049105577 | AI7: 2823 | AJ7: =AI7/AF7 -> 0.49508944 | AK7: 150 | AL7: =AK7/AF7 -> 0.026306559 | AM7: 1519 | AN7: =AM7/AF7 -> 0.26639776 | AO7: 930 | AP7: =AO7/AF7 -> 0.16310067 | AQ7: =SUM(U7,AF7) -> 11028 | AR7: =SUM(V7,AG7) -> 602 | AS7: =AR7/AQ7 -> 0.054588321 | AT7: =SUM(X7,AI7) -> 6432 | AU7: =AT7/AQ7 -> 0.58324266 | AV7: =SUM(Z7,AK7) -> 346 | AW7: =AV7/AQ7 -> 0.031374683 | AX7: =SUM(AB7,AM7) -> 1984 | AY7: =AX7/AQ7 -> 0.17990569 | AZ7: =SUM(AD7,AO7) -> 1664 | BA7: =AZ7/AQ7 -> 0.15088865 | BB7: 5228 | BC7: 1569 | BD7: =BC7/BB7 -> 0.30011477 | BE7: 5495 | BF7: 1629 | BG7: =BF7/BE7 -> 0.29645132 | BH7: =SUM(BB7,BE7) -> 10723 | BI7: =SUM(BC7,BF7) -> 3198 | BJ7: =BI7/BH7 -> 0.29823743 | BK7: 11028 | BL7: 3134 | BM7: =BL7/BK7 -> 0.28418571 | BN7: 5326 | BO7: 1217 | BP7: =BO7/BN7 -> 0.22850169 | BQ7: 5702 | BR7: 1917 | BS7: =BR7/BQ7 -> 0.33619783 | BT7: 46810 | BU7: 11576 | BV7: =BU7/BT7 -> 0.24729759 | BW7: =BU7/$BU7 -> 1 | BX7: 42815 | BY7: 11263 | BZ7: =BY7/BX7 -> 0.26306201 | CA7: =BY7/$BU7 -> 0.9729613 | CB7: 759 | CC7: 51 | CD7: =CC7/CB7 -> 0.067193676 | CE7: =CC7/$BU7 -> 0.0044056669 | CF7: 478 | CG7: 65 | CH7: =CG7/CF7 -> 0.13598326 | CI7: =CG7/$BU7 -> 0.0056150657 | CJ7: 359 | CK7: 51 | CL7: =CK7/CJ7 -> 0.14206128 | CM7: =CK7/$BU7 -> 0.0044056669 | CN7: 6 | CO7: 2 | CP7: =CO7/CN7 -> 0.33333333 | CQ7: =CO7/$BU7 -> 0.00017277125 | CR7: 275 | CS7: 4 | CT7: =CS7/CR7 -> 0.014545455 | CU7: =CS7/$BU7 -> 0.0003455425 | CV7: 644 | CW7: 53 | CX7: =CW7/CV7 -> 0.082298137 | CY7: =CW7/$BU7 -> 0.0045784381 | CZ7: 1749 | DA7: 91 | DB7: =DA7/CZ7 -> 0.052029731 | DC7: =DA7/BU7 -> 0.0078610919 | DD7: 5326 | DE7: 657 | DF7: 2194 | DG7: 1285 | DH7: 1190 | DI7: =DE7/DD7 -> 0.12335712 | DJ7: =DF7/DD7 -> 0.41194142 | DK7: =SUM(DG7:DH7)/DD7 -> 0.46470146 | DL7: 5702 | DM7: 490 | DN7: 2435 | DO7: 1570 | DP7: 1207 | DQ7: =DM7/DL7 -> 0.08593476 | DR7: =DN7/DL7 -> 0.42704314 | DS7: =SUM(DO7:DP7)/DL7 -> 0.4870221 | DT7: =SUM(DL7,DD7) -> 11028 | DU7: =SUM(DM7,DE7) -> 1147 | DV7: =SUM(DN7,DF7) -> 4629 | DW7: =SUM(DO7,DG7) -> 2855 | DX7: =SUM(DP7,DH7) -> 2397 | DY7: =DU7/DT7 -> 0.10400798 | DZ7: =DV7/DT7 -> 0.41974973 | EA7: =SUM(DW7:DX7)/DT7 -> 0.47624229 | EB7: 7065 | EC7: 663 | ED7: =EC7/$EB7 -> 0.093842887 | EE7: 1425 | EF7: =EE7/$EB7 -> 0.20169851 | EG7: 2524 | EH7: =EG7/$EB7 -> 0.35725407 | EI7: 3654 | EJ7: =EI7/$EB7 -> 0.51719745 | EK7: 5119 | EL7: =EK7/$EB7 -> 0.72455768 | EM7: 6080 | EN7: =EM7/$EB7 -> 0.86058033 | EO7: 65933 | EP7: 46080 | EQ7: 79497 | ER7: 83273 | ES7: 48481 | ET7: 5228 | EU7: 435 | EV7: =EU7/ET7 -> 0.083205815 | EW7: 5495 | EX7: 528 | EY7: =EX7/EW7 -> 0.096087352 | EZ7: =SUM(ET7,EW7) -> 10723 | FA7: =SUM(EU7,EX7) -> 963 | FB7: =FA7/EZ7 -> 0.089806957 | FC7: 10723 | FD7: 963 | FE7: =FD7/$FC7 -> 0.089806957 | FF7: 2161 | FG7: =FF7/$FC7 -> 0.20152942 | FH7: 2786 | FI7: =FH7/$FC7 -> 0.25981535 | FJ7: 3269 | FK7: =FJ7/$FC7 -> 0.30485871 | FL7: 5684 | FM7: =FL7/$FC7 -> 0.53007554 | FN7: 673 | FO7: 0.20933126 | FP7: 7 | FQ7: 0.0021772939 | FR7: 135 | FS7: 0.063950734 | FT7: 0 | FU7: 0 | FV7: 701 | FW7: 0.22446366 | FX7: 22 | FY7: 0.0070445085 | FZ7: 140 | GA7: 0.054284606 | GB7: 0 | GC7: 0 | GD7: 1649 | GE7: 0.14952847 | GF7: 29 | GG7: 0.0026296699 | GH7: 7065 | GI7: 1457 | GJ7: =GI7/GH7 -> 0.20622788 | GK7: 558 | GL7: =GK7/GI7 -> 0.38297872 | GM7: 633 | GN7: =GM7/GI7 -> 0.43445436 | GO7: 5608 | GP7: =GO7/GH7 -> 0.79377212 | GQ7: 4281 | GR7: =GQ7/GO7 -> 0.76337375 | GS7: 1310 | GT7: =GS7/GO7 -> 0.23359486
A8: Bayfield | B8: 16575 | C8: 6838 | D8: 5185 | E8: 1901 | F8: 497 | G8: =C8/B8 -> 0.41254902 | H8: =D8/B8 -> 0.31282051 | I8: =E8/B8 -> 0.1146908 | J8: =F8/B8 -> 0.029984917 | K8: 2623 | L8: =K8/D8 -> 0.50588235 | M8: 2562 | N8: =M8/D8 -> 0.49411765 | O8: 54.6 | P8: 7437 | Q8: 4514 | R8: =Q8/P8 -> 0.60696517 | S8: 3600 | T8: =S8/P8 -> 0.48406616 | U8: 2623 | V8: 125 | W8: =V8/U8 -> 0.047655356 | X8: 1892 | Y8: =X8/U8 -> 0.72131148 | Z8: 87 | AA8: =Z8/U8 -> 0.033168128 | AB8: 211 | AC8: =AB8/U8 -> 0.080442242 | AD8: 308 | AE8: =AD8/U8 -> 0.1174228 | AF8: 2562 | AG8: 110 | AH8: =AG8/AF8 -> 0.042935207 | AI8: 1489 | AJ8: =AI8/AF8 -> 0.58118657 | AK8: 18 | AL8: =AK8/AF8 -> 0.0070257611 | AM8: 601 | AN8: =AM8/AF8 -> 0.23458236 | AO8: 344 | AP8: =AO8/AF8 -> 0.1342701 | AQ8: =SUM(U8,AF8) -> 5185 | AR8: =SUM(V8,AG8) -> 235 | AS8: =AR8/AQ8 -> 0.045323047 | AT8: =SUM(X8,AI8) -> 3381 | AU8: =AT8/AQ8 -> 0.65207329 | AV8: =SUM(Z8,AK8) -> 105 | AW8: =AV8/AQ8 -> 0.020250723 | AX8: =SUM(AB8,AM8) -> 812 | AY8: =AX8/AQ8 -> 0.15660559 | AZ8: =SUM(AD8,AO8) -> 652 | BA8: =AZ8/AQ8 -> 0.12574735 | BB8: 2599 | BC8: 811 | BD8: =BC8/BB8 -> 0.31204309 | BE8: 2524 | BF8: 661 | BG8: =BF8/BE8 -> 0.2618859 | BH8: =SUM(BB8,BE8) -> 5123 | BI8: =SUM(BC8,BF8) -> 1472 | BJ8: =BI8/BH8 -> 0.28733164 | BK8: 5185 | BL8: 1231 | BM8: =BL8/BK8 -> 0.23741562 | BN8: 2623 | BO8: 507 | BP8: =BO8/BN8 -> 0.19329013 | BQ8: 2562 | BR8: 724 | BS8: =BR8/BQ8 -> 0.28259173 | BT8: 16838 | BU8: 5636 | BV8: =BU8/BT8 -> 0.33471909 | BW8: =BU8/$BU8 -> 1 | BX8: 14304 | BY8: 5283 | BZ8: =BY8/BX8 -> 0.36933725 | CA8: =BY8/$BU8 -> 0.93736693 | CB8: 108 | CC8: 11 | CD8: =CC8/CB8 -> 0.10185185 | CE8: =CC8/$BU8 -> 0.0019517388 | CF8: 1475 | CG8: 226 | CH8: =CG8/CF8 -> 0.15322034 | CI8: =CG8/$BU8 -> 0.040099361 | CJ8: 88 | CK8: 9 | CL8: =CK8/CJ8 -> 0.10227273 | CM8: =CK8/$BU8 -> 0.0015968772 | CN8: 2 | CO8: 1 | CP8: =CO8/CN8 -> 0.5 | CQ8: =CO8/$BU8 -> 0.0001774308 | CR8: 42 | CS8: 0 | CT8: =CS8/CR8 -> 0 | CU8: =CS8/$BU8 -> 0 | CV8: 460 | CW8: 65 | CX8: =CW8/CV8 -> 0.14130435 | CY8: =CW8/$BU8 -> 0.011533002 | CZ8: 401 | DA8: 41 | DB8: =DA8/CZ8 -> 0.10224439 | DC8: =DA8/BU8 -> 0.0072746629 | DD8: 2623 | DE8: 68 | DF8: 764 | DG8: 765 | DH8: 1026 | DI8: =DE8/DD8 -> 0.025924514 | DJ8: =DF8/DD8 -> 0.29126954 | DK8: =SUM(DG8:DH8)/DD8 -> 0.68280595 | DL8: 2562 | DM8: 146 | DN8: 671 | DO8: 798 | DP8: 947 | DQ8: =DM8/DL8 -> 0.056986729 | DR8: =DN8/DL8 -> 0.26190476 | DS8: =SUM(DO8:DP8)/DL8 -> 0.68110851 | DT8: =SUM(DL8,DD8) -> 5185 | DU8: =SUM(DM8,DE8) -> 214 | DV8: =SUM(DN8,DF8) -> 1435 | DW8: =SUM(DO8,DG8) -> 1563 | DX8: =SUM(DP8,DH8) -> 1973 | DY8: =DU8/DT8 -> 0.041272903 | DZ8: =DV8/DT8 -> 0.27675988 | EA8: =SUM(DW8:DX8)/DT8 -> 0.68196721 | EB8: 3288 | EC8: 256 | ED8: =EC8/$EB8 -> 0.077858881 | EE8: 575 | EF8: =EE8/$EB8 -> 0.17487835 | EG8: 953 | EH8: =EG8/$EB8 -> 0.28984185 | EI8: 1341 | EJ8: =EI8/$EB8 -> 0.40784672 | EK8: 2133 | EL8: =EK8/$EB8 -> 0.64872263 | EM8: 2680 | EN8: =EM8/$EB8 -> 0.81508516 | EO8: 71151 | EP8: 49375 | EQ8: 82287 | ER8: 90231 | ES8: 59286 | ET8: 2599 | EU8: 159 | EV8: =EU8/ET8 -> 0.061177376 | EW8: 2524 | EX8: 199 | EY8: =EX8/EW8 -> 0.078843106 | EZ8: =SUM(ET8,EW8) -> 5123 | FA8: =SUM(EU8,EX8) -> 358 | FB8: =FA8/EZ8 -> 0.069880929 | FC8: 5123 | FD8: 358 | FE8: =FD8/$FC8 -> 0.069880929 | FF8: 772 | FG8: =FF8/$FC8 -> 0.15069295 | FH8: 1078 | FI8: =FH8/$FC8 -> 0.21042358 | FJ8: 1272 | FK8: =FJ8/$FC8 -> 0.24829202 | FL8: 2196 | FM8: =FL8/$FC8 -> 0.42865508 | FN8: 388 | FO8: 0.2305407 | FP8: 11 | FQ8: 0.0065359477 | FR8: 66 | FS8: 0.070212766 | FT8: 0 | FU8: 0 | FV8: 395 | FW8: 0.2467208 | FX8: 7 | FY8: 0.0043722673 | FZ8: 69 | GA8: 0.071800208 | GB8: 0 | GC8: 0 | GD8: 918 | GE8: 0.17704918 | GF8: 18 | GG8: 0.0034715526 | GH8: 3288 | GI8: 374 | GJ8: =GI8/GH8 -> 0.11374696 | GK8: 152 | GL8: =GK8/GI8 -> 0.40641711 | GM8: 164 | GN8: =GM8/GI8 -> 0.43850267 | GO8: 2914 | GP8: =GO8/GH8 -> 0.88625304 | GQ8: 2264 | GR8: =GQ8/GO8 -> 0.77693892 | GS8: 645 | GT8: =GS8/GO8 -> 0.22134523
A9: Brown | B9: 270892 | C9: 61112 | D9: 44324 | E9: 17095 | F9: 4364 | G9: =C9/B9 -> 0.22559544 | H9: =D9/B9 -> 0.1636224 | I9: =E9/B9 -> 0.06310633 | J9: =F9/B9 -> 0.016109741 | K9: 20365 | L9: =K9/D9 -> 0.45945763 | M9: 23959 | N9: =M9/D9 -> 0.54054237 | O9: 38.2 | P9: 110933 | Q9: 42474 | R9: =Q9/P9 -> 0.38287976 | S9: 31870 | T9: =S9/P9 -> 0.28729053 | U9: 20365 | V9: 1234 | W9: =V9/U9 -> 0.060594157 | X9: 13136 | Y9: =X9/U9 -> 0.64502823 | Z9: 588 | AA9: =Z9/U9 -> 0.028873067 | AB9: 2245 | AC9: =AB9/U9 -> 0.11023815 | AD9: 3162 | AE9: =AD9/U9 -> 0.15526639 | AF9: 23959 | AG9: 1529 | AH9: =AG9/AF9 -> 0.063817355 | AI9: 10809 | AJ9: =AI9/AF9 -> 0.45114571 | AK9: 442 | AL9: =AK9/AF9 -> 0.018448182 | AM9: 7025 | AN9: =AM9/AF9 -> 0.29320923 | AO9: 4154 | AP9: =AO9/AF9 -> 0.17337952 | AQ9: =SUM(U9,AF9) -> 44324 | AR9: =SUM(V9,AG9) -> 2763 | AS9: =AR9/AQ9 -> 0.062336432 | AT9: =SUM(X9,AI9) -> 23945 | AU9: =AT9/AQ9 -> 0.54022651 | AV9: =SUM(Z9,AK9) -> 1030 | AW9: =AV9/AQ9 -> 0.023237975 | AX9: =SUM(AB9,AM9) -> 9270 | AY9: =AX9/AQ9 -> 0.20914177 | AZ9: =SUM(AD9,AO9) -> 7316 | BA9: =AZ9/AQ9 -> 0.16505731 | BB9: 20041 | BC9: 5841 | BD9: =BC9/BB9 -> 0.29145252 | BE9: 23462 | BF9: 5973 | BG9: =BF9/BE9 -> 0.25458188 | BH9: =SUM(BB9,BE9) -> 43503 | BI9: =SUM(BC9,BF9) -> 11814 | BJ9: =BI9/BH9 -> 0.27156748 | BK9: 44324 | BL9: 13782 | BM9: =BL9/BK9 -> 0.31093764 | BN9: 20365 | BO9: 4796 | BP9: =BO9/BN9 -> 0.23550209 | BQ9: 23959 | BR9: 8986 | BS9: =BR9/BQ9 -> 0.37505739 | BT9: 273909 | BU9: 47490 | BV9: =BU9/BT9 -> 0.17337875 | BW9: =BU9/$BU9 -> 1 | BX9: 212413 | BY9: 44327 | BZ9: =BY9/BX9 -> 0.20868308 | CA9: =BY9/$BU9 -> 0.9333965 | CB9: 8315 | CC9: 309 | CD9: =CC9/CB9 -> 0.037161756 | CE9: =CC9/$BU9 -> 0.006506633 | CF9: 6565 | CG9: 762 | CH9: =CG9/CF9 -> 0.11607007 | CI9: =CG9/$BU9 -> 0.016045483 | CJ9: 10647 | CK9: 547 | CL9: =CK9/CJ9 -> 0.051375974 | CM9: =CK9/$BU9 -> 0.011518214 | CN9: 133 | CO9: 16 | CP9: =CO9/CN9 -> 0.12030075 | CQ9: =CO9/$BU9 -> 0.00033691303 | CR9: 5458 | CS9: 31 | CT9: =CS9/CR9 -> 0.0056797362 | CU9: =CS9/$BU9 -> 0.000652769 | CV9: 6301 | CW9: 222 | CX9: =CW9/CV9 -> 0.035232503 | CY9: =CW9/$BU9 -> 0.0046746684 | CZ9: 29535 | DA9: 1307 | DB9: =DA9/CZ9 -> 0.044252582 | DC9: =DA9/BU9 -> 0.027521583 | DD9: 20365 | DE9: 1302 | DF9: 6554 | DG9: 6209 | DH9: 6300 | DI9: =DE9/DD9 -> 0.063933219 | DJ9: =DF9/DD9 -> 0.32182666 | DK9: =SUM(DG9:DH9)/DD9 -> 0.61424012 | DL9: 23959 | DM9: 1399 | DN9: 10781 | DO9: 6635 | DP9: 5144 | DQ9: =DM9/DL9 -> 0.058391419 | DR9: =DN9/DL9 -> 0.44997704 | DS9: =SUM(DO9:DP9)/DL9 -> 0.49163154 | DT9: =SUM(DL9,DD9) -> 44324 | DU9: =SUM(DM9,DE9) -> 2701 | DV9: =SUM(DN9,DF9) -> 17335 | DW9: =SUM(DO9,DG9) -> 12844 | DX9: =SUM(DP9,DH9) -> 11444 | DY9: =DU9/DT9 -> 0.060937641 | DZ9: =DV9/DT9 -> 0.39109737 | EA9: =SUM(DW9:DX9)/DT9 -> 0.54796499 | EB9: 28946 | EC9: 2480 | ED9: =EC9/$EB9 -> 0.085676777 | EE9: 5310 | EF9: =EE9/$EB9 -> 0.18344504 | EG9: 9006 | EH9: =EG9/$EB9 -> 0.31113107 | EI9: 12896 | EJ9: =EI9/$EB9 -> 0.44551924 | EK9: 18340 | EL9: =EK9/$EB9 -> 0.63359359 | EM9: 22539 | EN9: =EM9/$EB9 -> 0.77865681 | EO9: 79649 | EP9: 49858 | EQ9: 90857 | ER9: 92652 | ES9: 57169 | ET9: 20041 | EU9: 1466 | EV9: =EU9/ET9 -> 0.073150042 | EW9: 23462 | EX9: 2044 | EY9: =EX9/EW9 -> 0.087119598 | EZ9: =SUM(ET9,EW9) -> 43503 | FA9: =SUM(EU9,EX9) -> 3510 | FB9: =FA9/EZ9 -> 0.080684091 | FC9: 43503 | FD9: 3510 | FE9: =FD9/$FC9 -> 0.080684091 | FF9: 6539 | FG9: =FF9/$FC9 -> 0.15031147 | FH9: 9383 | FI9: =FH9/$FC9 -> 0.21568627 | FJ9: 10954 | FK9: =FJ9/$FC9 -> 0.25179873 | FL9: 18332 | FM9: =FL9/$FC9 -> 0.42139623 | FN9: 3261 | FO9: 0.24933099 | FP9: 66 | FQ9: 0.0050462574 | FR9: 329 | FS9: 0.045155092 | FT9: 0 | FU9: 0 | FV9: 2379 | FW9: 0.16812721 | FX9: 37 | FY9: 0.002614841 | FZ9: 579 | GA9: 0.059027424 | GB9: 0 | GC9: 0 | GD9: 6548 | GE9: 0.14773035 | GF9: 103 | GG9: 0.0023237975 | GH9: 28946 | GI9: 7917 | GJ9: =GI9/GH9 -> 0.27350929 | GK9: 3071 | GL9: =GK9/GI9 -> 0.38789946 | GM9: 4345 | GN9: =GM9/GI9 -> 0.548819 | GO9: 21029 | GP9: =GO9/GH9 -> 0.72649071 | GQ9: 16581 | GR9: =GQ9/GO9 -> 0.78848257 | GS9: 4277 | GT9: =GS9/GO9 -> 0.2033858
A10: Buffalo | B10: 13393 | C10: 4353 | D10: 3218 | E10: 1328 | F10: 382 | G10: =C10/B10 -> 0.32502053 | H10: =D10/B10 -> 0.24027477 | I10: =E10/B10 -> 0.099156276 | J10: =F10/B10 -> 0.028522362 | K10: 1637 | L10: =K10/D10 -> 0.50870106 | M10: 1581 | N10: =M10/D10 -> 0.49129894 | O10: 46.5 | P10: 5720 | Q10: 2948 | R10: =Q10/P10 -> 0.51538462 | S10: 2293 | T10: =S10/P10 -> 0.40087413 | U10: 1637 | V10: 129 | W10: =V10/U10 -> 0.078802688 | X10: 1092 | Y10: =X10/U10 -> 0.66707392 | Z10: 50 | AA10: =Z10/U10 -> 0.030543677 | AB10: 150 | AC10: =AB10/U10 -> 0.091631032 | AD10: 216 | AE10: =AD10/U10 -> 0.13194869 | AF10: 1581 | AG10: 45 | AH10: =AG10/AF10 -> 0.028462998 | AI10: 751 | AJ10: =AI10/AF10 -> 0.47501581 | AK10: 43 | AL10: =AK10/AF10 -> 0.027197976 | AM10: 493 | AN10: =AM10/AF10 -> 0.31182796 | AO10: 249 | AP10: =AO10/AF10 -> 0.15749526 | AQ10: =SUM(U10,AF10) -> 3218 | AR10: =SUM(V10,AG10) -> 174 | AS10: =AR10/AQ10 -> 0.054070851 | AT10: =SUM(X10,AI10) -> 1843 | AU10: =AT10/AQ10 -> 0.57271597 | AV10: =SUM(Z10,AK10) -> 93 | AW10: =AV10/AQ10 -> 0.028899938 | AX10: =SUM(AB10,AM10) -> 643 | AY10: =AX10/AQ10 -> 0.19981355 | AZ10: =SUM(AD10,AO10) -> 465 | BA10: =AZ10/AQ10 -> 0.14449969 | BB10: 1628 | BC10: 594 | BD10: =BC10/BB10 -> 0.36486486 | BE10: 1567 | BF10: 442 | BG10: =BF10/BE10 -> 0.28206765 | BH10: =SUM(BB10,BE10) -> 3195 | BI10: =SUM(BC10,BF10) -> 1036 | BJ10: =BI10/BH10 -> 0.32425665 | BK10: 3218 | BL10: 979 | BM10: =BL10/BK10 -> 0.30422623 | BN10: 1637 | BO10: 381 | BP10: =BO10/BN10 -> 0.23274282 | BQ10: 1581 | BR10: 598 | BS10: =BR10/BQ10 -> 0.37824162 | BT10: 13464 | BU10: 3434 | BV10: =BU10/BT10 -> 0.25505051 | BW10: =BU10/$BU10 -> 1 | BX10: 12699 | BY10: 3369 | BZ10: =BY10/BX10 -> 0.26529648 | CA10: =BY10/$BU10 -> 0.98107164 | CB10: 77 | CC10: 5 | CD10: =CC10/CB10 -> 0.064935065 | CE10: =CC10/$BU10 -> 0.001456028 | CF10: 54 | CG10: 7 | CH10: =CG10/CF10 -> 0.12962963 | CI10: =CG10/$BU10 -> 0.0020384391 | CJ10: 58 | CK10: 5 | CL10: =CK10/CJ10 -> 0.086206897 | CM10: =CK10/$BU10 -> 0.001456028 | CN10: 0 | CO10: 0 | CP10: 0 | CQ10: =CO10/$BU10 -> 0 | CR10: 132 | CS10: 0 | CT10: =CS10/CR10 -> 0 | CU10: =CS10/$BU10 -> 0 | CV10: 149 | CW10: 25 | CX10: =CW10/CV10 -> 0.16778523 | CY10: =CW10/$BU10 -> 0.0072801398 | CZ10: 427 | DA10: 23 | DB10: =DA10/CZ10 -> 0.053864169 | DC10: =DA10/BU10 -> 0.0066977286 | DD10: 1637 | DE10: 202 | DF10: 721 | DG10: 383 | DH10: 331 | DI10: =DE10/DD10 -> 0.12339646 | DJ10: =DF10/DD10 -> 0.44043983 | DK10: =SUM(DG10:DH10)/DD10 -> 0.43616371 | DL10: 1581 | DM10: 175 | DN10: 664 | DO10: 365 | DP10: 377 | DQ10: =DM10/DL10 -> 0.11068944 | DR10: =DN10/DL10 -> 0.41998735 | DS10: =SUM(DO10:DP10)/DL10 -> 0.46932321 | DT10: =SUM(DL10,DD10) -> 3218 | DU10: =SUM(DM10,DE10) -> 377 | DV10: =SUM(DN10,DF10) -> 1385 | DW10: =SUM(DO10,DG10) -> 748 | DX10: =SUM(DP10,DH10) -> 708 | DY10: =DU10/DT10 -> 0.11715351 | DZ10: =DV10/DT10 -> 0.43039155 | EA10: =SUM(DW10:DX10)/DT10 -> 0.45245494 | EB10: 2080 | EC10: 230 | ED10: =EC10/$EB10 -> 0.11057692 | EE10: 523 | EF10: =EE10/$EB10 -> 0.25144231 | EG10: 779 | EH10: =EG10/$EB10 -> 0.37451923 | EI10: 1101 | EJ10: =EI10/$EB10 -> 0.52932692 | EK10: 1525 | EL10: =EK10/$EB10 -> 0.73317308 | EM10: 1771 | EN10: =EM10/$EB10 -> 0.85144231 | EO10: 70479 | EP10: 44821 | EQ10: 86216 | ER10: 96181 | ES10: 46625 | ET10: 1628 | EU10: 120 | EV10: =EU10/ET10 -> 0.073710074 | EW10: 1567 | EX10: 222 | EY10: =EX10/EW10 -> 0.14167198 | EZ10: =SUM(ET10,EW10) -> 3195 | FA10: =SUM(EU10,EX10) -> 342 | FB10: =FA10/EZ10 -> 0.10704225 | FC10: 3195 | FD10: 342 | FE10: =FD10/$FC10 -> 0.10704225 | FF10: 680 | FG10: =FF10/$FC10 -> 0.21283255 | FH10: 944 | FI10: =FH10/$FC10 -> 0.29546166 | FJ10: 1058 | FK10: =FJ10/$FC10 -> 0.33114241 | FL10: 1674 | FM10: =FL10/$FC10 -> 0.52394366 | FN10: 319 | FO10: 0.31490622 | FP10: 24 | FQ10: 0.023692004 | FR10: 75 | FS10: 0.12019231 | FT10: 0 | FU10: 0 | FV10: 162 | FW10: 0.18472064 | FX10: 12 | FY10: 0.01368301 | FZ10: 32 | GA10: 0.045454545 | GB10: 0 | GC10: 0 | GD10: 588 | GE10: 0.18272219 | GF10: 36 | GG10: 0.011187073 | GH10: 2080 | GI10: 422 | GJ10: =GI10/GH10 -> 0.20288462 | GK10: 191 | GL10: =GK10/GI10 -> 0.45260664 | GM10: 148 | GN10: =GM10/GI10 -> 0.3507109 | GO10: 1658 | GP10: =GO10/GH10 -> 0.79711538 | GQ10: 1147 | GR10: =GQ10/GO10 -> 0.69179735 | GS10: 496 | GT10: =GS10/GO10 -> 0.29915561
A11: Burnett | B11: 16916 | C11: 7320 | D11: 5460 | E11: 2033 | F11: 516 | G11: =C11/B11 -> 0.43272641 | H11: =D11/B11 -> 0.32277134 | I11: =E11/B11 -> 0.12018208 | J11: =F11/B11 -> 0.030503665 | K11: 2804 | L11: =K11/D11 -> 0.51355311 | M11: 2656 | N11: =M11/D11 -> 0.48644689 | O11: 56 | P11: 7188 | Q11: 4678 | R11: =Q11/P11 -> 0.6508069 | S11: 3674 | T11: =S11/P11 -> 0.51112966 | U11: 2804 | V11: 196 | W11: =V11/U11 -> 0.069900143 | X11: 1693 | Y11: =X11/U11 -> 0.60378031 | Z11: 117 | AA11: =Z11/U11 -> 0.041726106 | AB11: 295 | AC11: =AB11/U11 -> 0.10520685 | AD11: 503 | AE11: =AD11/U11 -> 0.17938659 | AF11: 2656 | AG11: 128 | AH11: =AG11/AF11 -> 0.048192771 | AI11: 1514 | AJ11: =AI11/AF11 -> 0.57003012 | AK11: 33 | AL11: =AK11/AF11 -> 0.012424699 | AM11: 631 | AN11: =AM11/AF11 -> 0.2375753 | AO11: 350 | AP11: =AO11/AF11 -> 0.13177711 | AQ11: =SUM(U11,AF11) -> 5460 | AR11: =SUM(V11,AG11) -> 324 | AS11: =AR11/AQ11 -> 0.059340659 | AT11: =SUM(X11,AI11) -> 3207 | AU11: =AT11/AQ11 -> 0.58736264 | AV11: =SUM(Z11,AK11) -> 150 | AW11: =AV11/AQ11 -> 0.027472527 | AX11: =SUM(AB11,AM11) -> 926 | AY11: =AX11/AQ11 -> 0.16959707 | AZ11: =SUM(AD11,AO11) -> 853 | BA11: =AZ11/AQ11 -> 0.15622711 | BB11: 2794 | BC11: 900 | BD11: =BC11/BB11 -> 0.32211883 | BE11: 2617 | BF11: 735 | BG11: =BF11/BE11 -> 0.28085594 | BH11: =SUM(BB11,BE11) -> 5411 | BI11: =SUM(BC11,BF11) -> 1635 | BJ11: =BI11/BH11 -> 0.30216226 | BK11: 5460 | BL11: 1436 | BM11: =BL11/BK11 -> 0.26300366 | BN11: 2804 | BO11: 724 | BP11: =BO11/BN11 -> 0.25820257 | BQ11: 2656 | BR11: 712 | BS11: =BR11/BQ11 -> 0.26807229 | BT11: 17187 | BU11: 5899 | BV11: =BU11/BT11 -> 0.34322453 | BW11: =BU11/$BU11 -> 1 | BX11: 15579 | BY11: 5617 | BZ11: =BY11/BX11 -> 0.36054946 | CA11: =BY11/$BU11 -> 0.95219529 | CB11: 138 | CC11: 22 | CD11: =CC11/CB11 -> 0.15942029 | CE11: =CC11/$BU11 -> 0.0037294457 | CF11: 644 | CG11: 141 | CH11: =CG11/CF11 -> 0.2189441 | CI11: =CG11/$BU11 -> 0.023902356 | CJ11: 86 | CK11: 17 | CL11: =CK11/CJ11 -> 0.19767442 | CM11: =CK11/$BU11 -> 0.0028818444 | CN11: 9 | CO11: 2 | CP11: =CO11/CN11 -> 0.22222222 | CQ11: =CO11/$BU11 -> 0.00033904052 | CR11: 43 | CS11: 1 | CT11: =CS11/CR11 -> 0.023255814 | CU11: =CS11/$BU11 -> 0.00016952026 | CV11: 377 | CW11: 66 | CX11: =CW11/CV11 -> 0.17506631 | CY11: =CW11/$BU11 -> 0.011188337 | CZ11: 354 | DA11: 34 | DB11: =DA11/CZ11 -> 0.096045198 | DC11: =DA11/BU11 -> 0.0057636888 | DD11: 2804 | DE11: 254 | DF11: 989 | DG11: 851 | DH11: 710 | DI11: =DE11/DD11 -> 0.090584879 | DJ11: =DF11/DD11 -> 0.35271041 | DK11: =SUM(DG11:DH11)/DD11 -> 0.55670471 | DL11: 2656 | DM11: 140 | DN11: 1196 | DO11: 812 | DP11: 508 | DQ11: =DM11/DL11 -> 0.052710843 | DR11: =DN11/DL11 -> 0.4503012 | DS11: =SUM(DO11:DP11)/DL11 -> 0.49698795 | DT11: =SUM(DL11,DD11) -> 5460 | DU11: =SUM(DM11,DE11) -> 394 | DV11: =SUM(DN11,DF11) -> 2185 | DW11: =SUM(DO11,DG11) -> 1663 | DX11: =SUM(DP11,DH11) -> 1218 | DY11: =DU11/DT11 -> 0.072161172 | DZ11: =DV11/DT11 -> 0.40018315 | EA11: =SUM(DW11:DX11)/DT11 -> 0.52765568 | EB11: 3371 | EC11: 363 | ED11: =EC11/$EB11 -> 0.10768318 | EE11: 698 | EF11: =EE11/$EB11 -> 0.20706022 | EG11: 1126 | EH11: =EG11/$EB11 -> 0.33402551 | EI11: 1544 | EJ11: =EI11/$EB11 -> 0.45802433 | EK11: 2341 | EL11: =EK11/$EB11 -> 0.69445268 | EM11: 2720 | EN11: =EM11/$EB11 -> 0.80688223 | EO11: 62819 | EP11: 51250 | EQ11: 87500 | ER11: 71550 | ES11: 53472 | ET11: 2794 | EU11: 292 | EV11: =EU11/ET11 -> 0.10450966 | EW11: 2617 | EX11: 305 | EY11: =EX11/EW11 -> 0.11654566 | EZ11: =SUM(ET11,EW11) -> 5411 | FA11: =SUM(EU11,EX11) -> 597 | FB11: =FA11/EZ11 -> 0.11033081 | FC11: 5411 | FD11: 597 | FE11: =FD11/$FC11 -> 0.11033081 | FF11: 946 | FG11: =FF11/$FC11 -> 0.17482905 | FH11: 1348 | FI11: =FH11/$FC11 -> 0.24912216 | FJ11: 1465 | FK11: =FJ11/$FC11 -> 0.27074478 | FL11: 2521 | FM11: =FL11/$FC11 -> 0.46590279 | FN11: 323 | FO11: 0.18074986 | FP11: 6 | FQ11: 0.0033575825 | FR11: 58 | FS11: 0.057030482 | FT11: 2 | FU11: 0.0019665683 | FV11: 303 | FW11: 0.1847561 | FX11: 0 | FY11: 0 | FZ11: 51 | GA11: 0.05019685 | GB11: 0 | GC11: 0 | GD11: 735 | GE11: 0.13461538 | GF11: 8 | GG11: 0.0014652015 | GH11: 3371 | GI11: 448 | GJ11: =GI11/GH11 -> 0.13289825 | GK11: 176 | GL11: =GK11/GI11 -> 0.39285714 | GM11: 147 | GN11: =GM11/GI11 -> 0.328125 | GO11: 2923 | GP11: =GO11/GH11 -> 0.86710175 | GQ11: 2300 | GR11: =GQ11/GO11 -> 0.78686281 | GS11: 590 | GT11: =GS11/GO11 -> 0.20184742
A12: Calumet | B12: 52942 | C12: 12889 | D12: 9104 | E12: 3407 | F12: 885 | G12: =C12/B12 -> 0.2434551 | H12: =D12/B12 -> 0.17196177 | I12: =E12/B12 -> 0.064353443 | J12: =F12/B12 -> 0.016716407 | K12: 4298 | L12: =K12/D12 -> 0.47210018 | M12: 4806 | N12: =M12/D12 -> 0.52789982 | O12: 41.7 | P12: 21372 | Q12: 8792 | R12: =Q12/P12 -> 0.41137937 | S12: 6540 | T12: =S12/P12 -> 0.30600786 | U12: 4298 | V12: 294 | W12: =V12/U12 -> 0.068403909 | X12: 2953 | Y12: =X12/U12 -> 0.68706375 | Z12: 163 | AA12: =Z12/U12 -> 0.037924616 | AB12: 490 | AC12: =AB12/U12 -> 0.11400651 | AD12: 398 | AE12: =AD12/U12 -> 0.09260121 | AF12: 4806 | AG12: 181 | AH12: =AG12/AF12 -> 0.037661257 | AI12: 2593 | AJ12: =AI12/AF12 -> 0.53953392 | AK12: 89 | AL12: =AK12/AF12 -> 0.018518519 | AM12: 1325 | AN12: =AM12/AF12 -> 0.27569705 | AO12: 618 | AP12: =AO12/AF12 -> 0.12858926 | AQ12: =SUM(U12,AF12) -> 9104 | AR12: =SUM(V12,AG12) -> 475 | AS12: =AR12/AQ12 -> 0.052174868 | AT12: =SUM(X12,AI12) -> 5546 | AU12: =AT12/AQ12 -> 0.60918278 | AV12: =SUM(Z12,AK12) -> 252 | AW12: =AV12/AQ12 -> 0.027680141 | AX12: =SUM(AB12,AM12) -> 1815 | AY12: =AX12/AQ12 -> 0.19936292 | AZ12: =SUM(AD12,AO12) -> 1016 | BA12: =AZ12/AQ12 -> 0.1115993 | BB12: 4270 | BC12: 1155 | BD12: =BC12/BB12 -> 0.2704918 | BE12: 4750 | BF12: 1211 | BG12: =BF12/BE12 -> 0.25494737 | BH12: =SUM(BB12,BE12) -> 9020 | BI12: =SUM(BC12,BF12) -> 2366 | BJ12: =BI12/BH12 -> 0.26230599 | BK12: 9104 | BL12: 2547 | BM12: =BL12/BK12 -> 0.27976714 | BN12: 4298 | BO12: 984 | BP12: =BO12/BN12 -> 0.22894369 | BQ12: 4806 | BR12: 1563 | BS12: =BR12/BQ12 -> 0.32521848 | BT12: 53602 | BU12: 10036 | BV12: =BU12/BT12 -> 0.18723182 | BW12: =BU12/$BU12 -> 1 | BX12: 47077 | BY12: 9664 | BZ12: =BY12/BX12 -> 0.20528071 | CA12: =BY12/$BU12 -> 0.96293344 | CB12: 602 | CC12: 26 | CD12: =CC12/CB12 -> 0.043189369 | CE12: =CC12/$BU12 -> 0.0025906736 | CF12: 264 | CG12: 37 | CH12: =CG12/CF12 -> 0.14015152 | CI12: =CG12/$BU12 -> 0.0036867278 | CJ12: 1635 | CK12: 120 | CL12: =CK12/CJ12 -> 0.073394495 | CM12: =CK12/$BU12 -> 0.011956955 | CN12: 30 | CO12: 2 | CP12: =CO12/CN12 -> 0.066666667 | CQ12: =CO12/$BU12 -> 0.00019928258 | CR12: 329 | CS12: 0 | CT12: =CS12/CR12 -> 0 | CU12: =CS12/$BU12 -> 0 | CV12: 809 | CW12: 48 | CX12: =CW12/CV12 -> 0.059332509 | CY12: =CW12/$BU12 -> 0.004782782 | CZ12: 3185 | DA12: 139 | DB12: =DA12/CZ12 -> 0.043642072 | DC12: =DA12/BU12 -> 0.013850139 | DD12: 4298 | DE12: 304 | DF12: 1898 | DG12: 1165 | DH12: 931 | DI12: =DE12/DD12 -> 0.070730572 | DJ12: =DF12/DD12 -> 0.44160074 | DK12: =SUM(DG12:DH12)/DD12 -> 0.48766868 | DL12: 4806 | DM12: 319 | DN12: 2187 | DO12: 1523 | DP12: 777 | DQ12: =DM12/DL12 -> 0.066375364 | DR12: =DN12/DL12 -> 0.45505618 | DS12: =SUM(DO12:DP12)/DL12 -> 0.47856846 | DT12: =SUM(DL12,DD12) -> 9104 | DU12: =SUM(DM12,DE12) -> 623 | DV12: =SUM(DN12,DF12) -> 4085 | DW12: =SUM(DO12,DG12) -> 2688 | DX12: =SUM(DP12,DH12) -> 1708 | DY12: =DU12/DT12 -> 0.068431459 | DZ12: =DV12/DT12 -> 0.44870387 | EA12: =SUM(DW12:DX12)/DT12 -> 0.48286467 | EB12: 6028 | EC12: 406 | ED12: =EC12/$EB12 -> 0.067352356 | EE12: 942 | EF12: =EE12/$EB12 -> 0.15627074 | EG12: 1961 | EH12: =EG12/$EB12 -> 0.3253152 | EI12: 2979 | EJ12: =EI12/$EB12 -> 0.49419376 | EK12: 4506 | EL12: =EK12/$EB12 -> 0.74751161 | EM12: 5120 | EN12: =EM12/$EB12 -> 0.84936961 | EO12: 88810 | EP12: 43631 | EQ12: 112699 | ER12: 112092 | ES12: 50433 | ET12: 4270 | EU12: 341 | EV12: =EU12/ET12 -> 0.079859485 | EW12: 4750 | EX12: 492 | EY12: =EX12/EW12 -> 0.10357895 | EZ12: =SUM(ET12,EW12) -> 9020 | FA12: =SUM(EU12,EX12) -> 833 | FB12: =FA12/EZ12 -> 0.092350333 | FC12: 9020 | FD12: 833 | FE12: =FD12/$FC12 -> 0.092350333 | FF12: 1301 | FG12: =FF12/$FC12 -> 0.14423503 | FH12: 2009 | FI12: =FH12/$FC12 -> 0.22272727 | FJ12: 2191 | FK12: =FJ12/$FC12 -> 0.24290466 | FL12: 4472 | FM12: =FL12/$FC12 -> 0.49578714 | FN12: 516 | FO12: 0.18527828 | FP12: 0 | FQ12: 0 | FR12: 97 | FS12: 0.064111038 | FT12: 0 | FU12: 0 | FV12: 581 | FW12: 0.19951923 | FX12: 25 | FY12: 0.0085851648 | FZ12: 38 | GA12: 0.020063358 | GB12: 0 | GC12: 0 | GD12: 1232 | GE12: 0.13532513 | GF12: 25 | GG12: 0.0027460457 | GH12: 6028 | GI12: 1074 | GJ12: =GI12/GH12 -> 0.17816855 | GK12: 311 | GL12: =GK12/GI12 -> 0.28957169 | GM12: 691 | GN12: =GM12/GI12 -> 0.6433892 | GO12: 4954 | GP12: =GO12/GH12 -> 0.82183145 | GQ12: 3691 | GR12: =GQ12/GO12 -> 0.7450545 | GS12: 1222 | GT12: =GS12/GO12 -> 0.24666936
A13: Chippewa | B13: 66799 | C13: 18379 | D13: 13188 | E13: 5270 | F13: 1582 | G13: =C13/B13 -> 0.27513885 | H13: =D13/B13 -> 0.19742811 | I13: =E13/B13 -> 0.078893397 | J13: =F13/B13 -> 0.023682989 | K13: 6307 | L13: =K13/D13 -> 0.47823779 | M13: 6881 | N13: =M13/D13 -> 0.52176221 | O13: 42.2 | P13: 27139 | Q13: 12125 | R13: =Q13/P13 -> 0.44677402 | S13: 9155 | T13: =S13/P13 -> 0.33733741 | U13: 6307 | V13: 353 | W13: =V13/U13 -> 0.055969558 | X13: 4148 | Y13: =X13/U13 -> 0.65768194 | Z13: 96 | AA13: =Z13/U13 -> 0.015221183 | AB13: 869 | AC13: =AB13/U13 -> 0.13778342 | AD13: 841 | AE13: =AD13/U13 -> 0.1333439 | AF13: 6881 | AG13: 429 | AH13: =AG13/AF13 -> 0.062345589 | AI13: 3303 | AJ13: =AI13/AF13 -> 0.48001744 | AK13: 107 | AL13: =AK13/AF13 -> 0.015550065 | AM13: 1986 | AN13: =AM13/AF13 -> 0.28862084 | AO13: 1056 | AP13: =AO13/AF13 -> 0.15346607 | AQ13: =SUM(U13,AF13) -> 13188 | AR13: =SUM(V13,AG13) -> 782 | AS13: =AR13/AQ13 -> 0.05929633 | AT13: =SUM(X13,AI13) -> 7451 | AU13: =AT13/AQ13 -> 0.56498332 | AV13: =SUM(Z13,AK13) -> 203 | AW13: =AV13/AQ13 -> 0.015392781 | AX13: =SUM(AB13,AM13) -> 2855 | AY13: =AX13/AQ13 -> 0.21648468 | AZ13: =SUM(AD13,AO13) -> 1897 | BA13: =AZ13/AQ13 -> 0.14384289 | BB13: 6139 | BC13: 1708 | BD13: =BC13/BB13 -> 0.27822121 | BE13: 6666 | BF13: 1724 | BG13: =BF13/BE13 -> 0.25862586 | BH13: =SUM(BB13,BE13) -> 12805 | BI13: =SUM(BC13,BF13) -> 3432 | BJ13: =BI13/BH13 -> 0.2680203 | BK13: 13188 | BL13: 3893 | BM13: =BL13/BK13 -> 0.2951926 | BN13: 6307 | BO13: 1516 | BP13: =BO13/BN13 -> 0.24036785 | BQ13: 6881 | BR13: 2377 | BS13: =BR13/BQ13 -> 0.34544398 | BT13: 67323 | BU13: 14023 | BV13: =BU13/BT13 -> 0.20829434 | BW13: =BU13/$BU13 -> 1 | BX13: 62476 | BY13: 13708 | BZ13: =BY13/BX13 -> 0.21941225 | CA13: =BY13/$BU13 -> 0.9775369 | CB13: 1102 | CC13: 27 | CD13: =CC13/CB13 -> 0.024500907 | CE13: =CC13/$BU13 -> 0.0019254083 | CF13: 349 | CG13: 52 | CH13: =CG13/CF13 -> 0.14899713 | CI13: =CG13/$BU13 -> 0.0037081937 | CJ13: 1005 | CK13: 85 | CL13: =CK13/CJ13 -> 0.084577114 | CM13: =CK13/$BU13 -> 0.0060614704 | CN13: 24 | CO13: 4 | CP13: =CO13/CN13 -> 0.16666667 | CQ13: =CO13/$BU13 -> 0.00028524567 | CR13: 153 | CS13: 0 | CT13: =CS13/CR13 -> 0 | CU13: =CS13/$BU13 -> 0 | CV13: 977 | CW13: 74 | CX13: =CW13/CV13 -> 0.075742068 | CY13: =CW13/$BU13 -> 0.0052770449 | CZ13: 1390 | DA13: 73 | DB13: =DA13/CZ13 -> 0.052517986 | DC13: =DA13/BU13 -> 0.0052057334 | DD13: 6307 | DE13: 491 | DF13: 2719 | DG13: 1769 | DH13: 1328 | DI13: =DE13/DD13 -> 0.077850008 | DJ13: =DF13/DD13 -> 0.43110829 | DK13: =SUM(DG13:DH13)/DD13 -> 0.4910417 | DL13: 6881 | DM13: 310 | DN13: 3108 | DO13: 2166 | DP13: 1297 | DQ13: =DM13/DL13 -> 0.045051591 | DR13: =DN13/DL13 -> 0.45167854 | DS13: =SUM(DO13:DP13)/DL13 -> 0.50326987 | DT13: =SUM(DL13,DD13) -> 13188 | DU13: =SUM(DM13,DE13) -> 801 | DV13: =SUM(DN13,DF13) -> 5827 | DW13: =SUM(DO13,DG13) -> 3935 | DX13: =SUM(DP13,DH13) -> 2625 | DY13: =DU13/DT13 -> 0.060737034 | DZ13: =DV13/DT13 -> 0.44184107 | EA13: =SUM(DW13:DX13)/DT13 -> 0.4974219 | EB13: 8369 | EC13: 797 | ED13: =EC13/$EB13 -> 0.095232405 | EE13: 1551 | EF13: =EE13/$EB13 -> 0.1853268 | EG13: 2847 | EH13: =EG13/$EB13 -> 0.34018401 | EI13: 4007 | EJ13: =EI13/$EB13 -> 0.47879078 | EK13: 5792 | EL13: =EK13/$EB13 -> 0.69207791 | EM13: 6832 | EN13: =EM13/$EB13 -> 0.81634604 | EO13: 74680 | EP13: 49836 | EQ13: 92635 | ER13: 94612 | ES13: 51546 | ET13: 6139 | EU13: 513 | EV13: =EU13/ET13 -> 0.083564098 | EW13: 6666 | EX13: 676 | EY13: =EX13/EW13 -> 0.10141014 | EZ13: =SUM(ET13,EW13) -> 12805 | FA13: =SUM(EU13,EX13) -> 1189 | FB13: =FA13/EZ13 -> 0.092854354 | FC13: 12805 | FD13: 1189 | FE13: =FD13/$FC13 -> 0.092854354 | FF13: 2008 | FG13: =FF13/$FC13 -> 0.15681374 | FH13: 2820 | FI13: =FH13/$FC13 -> 0.22022647 | FJ13: 3678 | FK13: =FJ13/$FC13 -> 0.28723155 | FL13: 6043 | FM13: =FL13/$FC13 -> 0.47192503 | FN13: 1035 | FO13: 0.26005025 | FP13: 28 | FQ13: 0.0070351759 | FR13: 150 | FS13: 0.064460679 | FT13: 0 | FU13: 0 | FV13: 904 | FW13: 0.22955815 | FX13: 3 | FY13: 0.00076180802 | FZ13: 81 | GA13: 0.027522936 | GB13: 6 | GC13: 0.002038736 | GD13: 2170 | GE13: 0.16454352 | GF13: 37 | GG13: 0.0028055808 | GH13: 8369 | GI13: 1617 | GJ13: =GI13/GH13 -> 0.19321305 | GK13: 606 | GL13: =GK13/GI13 -> 0.37476809 | GM13: 896 | GN13: =GM13/GI13 -> 0.55411255 | GO13: 6752 | GP13: =GO13/GH13 -> 0.80678695 | GQ13: 5347 | GR13: =GQ13/GO13 -> 0.79191351 | GS13: 1343 | GT13: =GS13/GO13 -> 0.19890403
